<?xml version="1.0"?>

<robot name="erica_robot" xmlns:xacro="http://www.ros.org/wiki/xacro">

  <xacro:property name="pi" value="3.141592654" />
   <!-- Import all Gazebo-customization elements, including Gazebo colors -->
  <xacro:include filename="$(find erica_description)/urdf/erica_gazebo.gazebo" />
  <xacro:include filename="$(find erica_description)/urdf/materials.xacro" />

  <!-- Used for fixing robot -->
<!--
  <link name="world">
  </link>

  <joint name="world_fixed" type="fixed">
    <origin xyz="0 0 0.7" rpy="0 0 0"/>
    <parent link="world"/>
    <child link="pelvis"/>
  </joint>
-->

  <link name="base">
  </link>

  <joint name="base_fixed" type="fixed">
    <origin xyz="0 0 0.9" rpy="0 0 0"/>
    <parent link="base"/>
    <child link="body_main"/>
  </joint>

  <!-- main -->

 <link name="body_main">
    <collision>
      <origin xyz="0 0 0" rpy="0 0 0"/>
         <geometry>
          <mesh filename="package://erica_description/meshes/asm_don_big_main.stl" scale="0.001 0.001 0.001"/>
        </geometry>
    </collision>

    <visual>
        <origin xyz="0 0 0" rpy="0 0 0"/>
        <geometry>
          <mesh filename="package://erica_description/meshes/asm_don_big_main.stl" scale="0.001 0.001 0.001"/>
        </geometry>
        <material name="red"/>
    </visual>

    <inertial>
      <origin xyz="0 0 0" rpy="0 0 0"/>      
      <mass value="1"/>
      <inertia ixx="1.0" ixy="0.0" ixz="0.0" iyy="1.0" iyz="0.0" izz="1.0" />      
    </inertial>
  </link>

  <!-- left_arm -->
  <!-- left_arm_pitch -->
 <joint name="l_arm_shoulder_pitch" type="revolute">
    <parent link="body_main"/>
    <child link="l_arm_shoulder_pitch_link"/>
    <origin xyz="0 0.113 0" rpy="0 0 0"/>
    <axis xyz="0 1 0"/>
    <limit velocity="6.5" effort="1000" lower="${-pi/2}" upper="${pi}" />
    <dynamics damping = "0.7"/>
  </joint>

  <transmission name="l_arm_shoulder_pitch_tran">
     <type>transmission_interface/SimpleTransmission</type>
     <joint name="l_arm_shoulder_pitch">
       <hardwareInterface>EffortJointInterface</hardwareInterface>
     </joint>
     <actuator name="l_arm_shoulder_pitch_motor">
       <hardwareInterface>EffortJointInterface</hardwareInterface>
       <mechanicalReduction>1</mechanicalReduction>
     </actuator>
  </transmission>

  <link name="l_arm_shoulder_pitch_link">
    <collision>
      <origin xyz="0 0 0" rpy="0 0 0"/>
      <geometry>
          <mesh filename="package://erica_description/meshes/asm_don_big_arm_l-1.stl" scale="0.001 0.001 0.001"/>
        </geometry>
    </collision>

    <visual>
        <origin xyz="0 0 0" rpy="0 0 0"/>
        <geometry>
          <mesh filename="package://erica_description/meshes/asm_don_big_arm_l-1.stl" scale="0.001 0.001 0.001"/>
        </geometry>
        <material name="red"/>
    </visual>

    <inertial>
      <origin xyz="0 0 0" rpy="0 0 0"/>      
      <mass value="1"/>
      <inertia ixx="1.0" ixy="0.0" ixz="0.0" iyy="1.0" iyz="0.0" izz="1.0" />      
    </inertial>
  </link>

  <!-- left_arm_roll -->

 <joint name="l_arm_shoulder_roll" type="revolute">
    <parent link="l_arm_shoulder_pitch_link"/>
    <child link="l_arm_shoulder_roll_link"/>
    <origin xyz="0 0.097 0" rpy="0 0 0"/>
    <axis xyz="0 1 0"/>
    <limit velocity="6.5" effort="1000" lower="${-pi/2}" upper="${pi}" />
    <dynamics damping = "0.7"/>
  </joint>

  <transmission name="l_arm_shoulder_roll_tran">
     <type>transmission_interface/SimpleTransmission</type>
     <joint name="l_arm_shoulder_roll">
       <hardwareInterface>EffortJointInterface</hardwareInterface>
     </joint>
     <actuator name="l_arm_shoulder_roll_motor">
       <hardwareInterface>EffortJointInterface</hardwareInterface>
       <mechanicalReduction>1</mechanicalReduction>
     </actuator>
  </transmission>

  <link name="l_arm_shoulder_roll_link">
    <collision>
      <origin xyz="0 0 0" rpy="0 0 0"/>
      <geometry>
          <mesh filename="package://erica_description/meshes/asm_don_big_arm_l-2.stl" scale="0.001 0.001 0.001"/>
        </geometry>
    </collision>

    <visual>
        <origin xyz="0 0 0" rpy="0 0 0"/>
        <geometry>
          <mesh filename="package://erica_description/meshes/asm_don_big_arm_l-2.stl" scale="0.001 0.001 0.001"/>
        </geometry>
        <material name="red"/>
    </visual>

    <inertial>
      <origin xyz="0 0 0" rpy="0 0 0"/>      
      <mass value="1"/>
      <inertia ixx="1.0" ixy="0.0" ixz="0.0" iyy="1.0" iyz="0.0" izz="1.0" />      
    </inertial>
  </link>

  <!-- left_arm_yaw -->

<joint name="l_arm_shoulder_yaw" type="revolute">
    <parent link="l_arm_shoulder_roll_link"/>
    <child link="l_arm_shoulder_yaw_link"/>
    <origin xyz="0 0 -0.047" rpy="0 0 0"/>
    <axis xyz="0 1 0"/>
    <limit velocity="6.5" effort="1000" lower="${-pi/2}" upper="${pi}" />
    <dynamics damping = "0.7"/>
  </joint>

  <transmission name="l_arm_shoulder_yaw_tran">
     <type>transmission_interface/SimpleTransmission</type>
     <joint name="l_arm_shoulder_yaw">
       <hardwareInterface>EffortJointInterface</hardwareInterface>
     </joint>
     <actuator name="l_arm_shoulder_yaw_motor">
       <hardwareInterface>EffortJointInterface</hardwareInterface>
       <mechanicalReduction>1</mechanicalReduction>
     </actuator>
  </transmission>

  <link name="l_arm_shoulder_yaw_link">
    <collision>
      <origin xyz="0 0 0" rpy="0 0 0"/>
      <geometry>
          <mesh filename="package://erica_description/meshes/asm_don_big_arm_l-3.stl" scale="0.001 0.001 0.001"/>
        </geometry>
    </collision>

    <visual>
        <origin xyz="0 0 0" rpy="0 0 0"/>
        <geometry>
          <mesh filename="package://erica_description/meshes/asm_don_big_arm_l-3.stl" scale="0.001 0.001 0.001"/>
        </geometry>
        <material name="red"/>
    </visual>

    <inertial>
      <origin xyz="0 0 0" rpy="0 0 0"/>      
      <mass value="1"/>
      <inertia ixx="1.0" ixy="0.0" ixz="0.0" iyy="1.0" iyz="0.0" izz="1.0" />      
    </inertial>
  </link>
  <!-- left_arm_elbow -->

<joint name="l_arm_elbow_pitch" type="revolute">
    <parent link="l_arm_shoulder_yaw_link"/>
    <child link="l_arm_elbow_pitch_link"/>
    <origin xyz="0 0 -0.153" rpy="0 0 0"/>
    <axis xyz="0 1 0"/>
    <limit velocity="6.5" effort="1000" lower="${-pi/2}" upper="${pi}" />
    <dynamics damping = "0.7"/>
  </joint>

  <transmission name="l_arm_elbow_pitch_tran">
     <type>transmission_interface/SimpleTransmission</type>
     <joint name="l_arm_elbow_pitch">
       <hardwareInterface>EffortJointInterface</hardwareInterface>
     </joint>
     <actuator name="l_arm_elbow_pitch_motor">
       <hardwareInterface>EffortJointInterface</hardwareInterface>
       <mechanicalReduction>1</mechanicalReduction>
     </actuator>
  </transmission>

  <link name="l_arm_elbow_pitch_link">
    <collision>
      <origin xyz="0 0 0" rpy="0 0 0"/>
      <geometry>
          <mesh filename="package://erica_description/meshes/asm_don_big_arm_l-4.stl" scale="0.001 0.001 0.001"/>
        </geometry>
    </collision>

    <visual>
        <origin xyz="0 0 0" rpy="0 0 0"/>
        <geometry>
          <mesh filename="package://erica_description/meshes/asm_don_big_arm_l-4.stl" scale="0.001 0.001 0.001"/>
        </geometry>
        <material name="red"/>
    </visual>

    <inertial>
      <origin xyz="0 0 0" rpy="0 0 0"/>      
      <mass value="1"/>
      <inertia ixx="1.0" ixy="0.0" ixz="0.0" iyy="1.0" iyz="0.0" izz="1.0" />      
    </inertial>
  </link>

  <!-- left_arm_wrist_pitch -->

<joint name="l_arm_wrist_pitch" type="revolute">
    <parent link="l_arm_elbow_pitch_link"/>
    <child link="l_arm_wrist_pitch_link"/>
    <origin xyz="0 0 -0.2" rpy="0 0 0"/>
    <axis xyz="0 1 0"/>
    <limit velocity="6.5" effort="1000" lower="${-pi/2}" upper="${pi}" />
    <dynamics damping = "0.7"/>
  </joint>

  <transmission name="l_arm_wrist_pitch_tran">
     <type>transmission_interface/SimpleTransmission</type>
     <joint name="l_arm_wrist_pitch">
       <hardwareInterface>EffortJointInterface</hardwareInterface>
     </joint>
     <actuator name="l_arm_wrist_pitch_motor">
       <hardwareInterface>EffortJointInterface</hardwareInterface>
       <mechanicalReduction>1</mechanicalReduction>
     </actuator>
  </transmission>

  <link name="l_arm_wrist_pitch_link">
    <collision>
      <origin xyz="0 0 0" rpy="0 0 0"/>
      <geometry>
          <mesh filename="package://erica_description/meshes/asm_don_big_arm_l-5.stl" scale="0.001 0.001 0.001"/>
        </geometry>
    </collision>

    <visual>
        <origin xyz="0 0 0" rpy="0 0 0"/>
        <geometry>
          <mesh filename="package://erica_description/meshes/asm_don_big_arm_l-5.stl" scale="0.001 0.001 0.001"/>
        </geometry>
        <material name="red"/>
    </visual>

    <inertial>
      <origin xyz="0 0 0" rpy="0 0 0"/>      
      <mass value="1"/>
      <inertia ixx="1.0" ixy="0.0" ixz="0.0" iyy="1.0" iyz="0.0" izz="1.0" />      
    </inertial>
  </link>

<!-- left_arm_wrist_roll -->

<joint name="l_arm_wrist_roll" type="revolute">
    <parent link="l_arm_wrist_pitch_link"/>
    <child link="l_arm_wrist_roll_link"/>
    <origin xyz="0 0 0" rpy="0 0 0"/>
    <axis xyz="0 1 0"/>
    <limit velocity="6.5" effort="1000" lower="${-pi/2}" upper="${pi}" />
    <dynamics damping = "0.7"/>
  </joint>

  <transmission name="l_arm_wrist_roll_tran">
     <type>transmission_interface/SimpleTransmission</type>
     <joint name="l_arm_wrist_roll">
       <hardwareInterface>EffortJointInterface</hardwareInterface>
     </joint>
     <actuator name="l_arm_wrist_roll_motor">
       <hardwareInterface>EffortJointInterface</hardwareInterface>
       <mechanicalReduction>1</mechanicalReduction>
     </actuator>
  </transmission>

  <link name="l_arm_wrist_roll_link">
    <collision>
      <origin xyz="0 0 0" rpy="0 0 0"/>
      <geometry>
          <mesh filename="package://erica_description/meshes/asm_don_big_arm_l-6.stl" scale="0.001 0.001 0.001"/>
        </geometry>
    </collision>

    <visual>
        <origin xyz="0 0 0" rpy="0 0 0"/>
        <geometry>
          <mesh filename="package://erica_description/meshes/asm_don_big_arm_l-6.stl" scale="0.001 0.001 0.001"/>
        </geometry>
        <material name="red"/>
    </visual>

    <inertial>
      <origin xyz="0 0 0" rpy="0 0 0"/>      
      <mass value="1"/>
      <inertia ixx="1.0" ixy="0.0" ixz="0.0" iyy="1.0" iyz="0.0" izz="1.0" />      
    </inertial>
  </link>



    <!-- right_arm -->
  <!-- right_arm_pitch -->
 <joint name="r_arm_shoulder_pitch" type="revolute">
    <parent link="body_main"/>
    <child link="r_arm_shoulder_pitch_link"/>
    <origin xyz="0 -0.113 0" rpy="0 0 0"/>
    <axis xyz="0 1 0"/>
    <limit velocity="6.5" effort="1000" lower="${-pi/2}" upper="${pi}" />
    <dynamics damping = "0.7"/>
  </joint>

  <transmission name="r_arm_shoulder_pitch_tran">
     <type>transmission_interface/SimpleTransmission</type>
     <joint name="r_arm_shoulder_pitch">
       <hardwareInterface>EffortJointInterface</hardwareInterface>
     </joint>
     <actuator name="r_arm_shoulder_pitch_motor">
       <hardwareInterface>EffortJointInterface</hardwareInterface>
       <mechanicalReduction>1</mechanicalReduction>
     </actuator>
  </transmission>

  <link name="r_arm_shoulder_pitch_link">
    <collision>
      <origin xyz="0 0 0" rpy="0 0 0"/>
      <geometry>
          <mesh filename="package://erica_description/meshes/asm_don_big_arm_r-1.stl" scale="0.001 0.001 0.001"/>
        </geometry>
    </collision>

    <visual>
        <origin xyz="0 0 0" rpy="0 0 0"/>
        <geometry>
          <mesh filename="package://erica_description/meshes/asm_don_big_arm_r-1.stl" scale="0.001 0.001 0.001"/>
        </geometry>
        <material name="red"/>
    </visual>

    <inertial>
      <origin xyz="0 0 0" rpy="0 0 0"/>      
      <mass value="1"/>
      <inertia ixx="1.0" ixy="0.0" ixz="0.0" iyy="1.0" iyz="0.0" izz="1.0" />      
    </inertial>
  </link>

  <!-- right_arm_roll -->

 <joint name="r_arm_shoulder_roll" type="revolute">
    <parent link="r_arm_shoulder_pitch_link"/>
    <child link="r_arm_shoulder_roll_link"/>
    <origin xyz="0 -0.097 0" rpy="0 0 0"/>
    <axis xyz="0 1 0"/>
    <limit velocity="6.5" effort="1000" lower="${-pi/2}" upper="${pi}" />
    <dynamics damping = "0.7"/>
  </joint>

  <transmission name="r_arm_shoulder_roll_tran">
     <type>transmission_interface/SimpleTransmission</type>
     <joint name="r_arm_shoulder_roll">
       <hardwareInterface>EffortJointInterface</hardwareInterface>
     </joint>
     <actuator name="r_arm_shoulder_roll_motor">
       <hardwareInterface>EffortJointInterface</hardwareInterface>
       <mechanicalReduction>1</mechanicalReduction>
     </actuator>
  </transmission>

  <link name="r_arm_shoulder_roll_link">
    <collision>
      <origin xyz="0 0 0" rpy="0 0 0"/>
      <geometry>
          <mesh filename="package://erica_description/meshes/asm_don_big_arm_r-2.stl" scale="0.001 0.001 0.001"/>
        </geometry>
    </collision>

    <visual>
        <origin xyz="0 0 0" rpy="0 0 0"/>
        <geometry>
          <mesh filename="package://erica_description/meshes/asm_don_big_arm_r-2.stl" scale="0.001 0.001 0.001"/>
        </geometry>
        <material name="red"/>
    </visual>

    <inertial>
      <origin xyz="0 0 0" rpy="0 0 0"/>      
      <mass value="1"/>
      <inertia ixx="1.0" ixy="0.0" ixz="0.0" iyy="1.0" iyz="0.0" izz="1.0" />      
    </inertial>
  </link>

  <!-- right_arm_yaw -->

<joint name="r_arm_shoulder_yaw" type="revolute">
    <parent link="r_arm_shoulder_roll_link"/>
    <child link="r_arm_shoulder_yaw_link"/>
    <origin xyz="0 0 -0.047" rpy="0 0 0"/>
    <axis xyz="0 1 0"/>
    <limit velocity="6.5" effort="1000" lower="${-pi/2}" upper="${pi}" />
    <dynamics damping = "0.7"/>
  </joint>

  <transmission name="r_arm_shoulder_yaw_tran">
     <type>transmission_interface/SimpleTransmission</type>
     <joint name="r_arm_shoulder_yaw">
       <hardwareInterface>EffortJointInterface</hardwareInterface>
     </joint>
     <actuator name="r_arm_shoulder_yaw_motor">
       <hardwareInterface>EffortJointInterface</hardwareInterface>
       <mechanicalReduction>1</mechanicalReduction>
     </actuator>
  </transmission>

  <link name="r_arm_shoulder_yaw_link">
    <collision>
      <origin xyz="0 0 0" rpy="0 0 0"/>
      <geometry>
          <mesh filename="package://erica_description/meshes/asm_don_big_arm_r-3.stl" scale="0.001 0.001 0.001"/>
        </geometry>
    </collision>

    <visual>
        <origin xyz="0 0 0" rpy="0 0 0"/>
        <geometry>
          <mesh filename="package://erica_description/meshes/asm_don_big_arm_r-3.stl" scale="0.001 0.001 0.001"/>
        </geometry>
        <material name="red"/>
    </visual>

    <inertial>
      <origin xyz="0 0 0" rpy="0 0 0"/>      
      <mass value="1"/>
      <inertia ixx="1.0" ixy="0.0" ixz="0.0" iyy="1.0" iyz="0.0" izz="1.0" />      
    </inertial>
  </link>
  <!-- right_arm_elbow -->

<joint name="r_arm_elbow_pitch" type="revolute">
    <parent link="r_arm_shoulder_yaw_link"/>
    <child link="r_arm_elbow_pitch_link"/>
    <origin xyz="0 0 -0.153" rpy="0 0 0"/>
    <axis xyz="0 1 0"/>
    <limit velocity="6.5" effort="1000" lower="${-pi/2}" upper="${pi}" />
    <dynamics damping = "0.7"/>
  </joint>

  <transmission name="r_arm_elbow_pitch_tran">
     <type>transmission_interface/SimpleTransmission</type>
     <joint name="r_arm_elbow_pitch">
       <hardwareInterface>EffortJointInterface</hardwareInterface>
     </joint>
     <actuator name="r_arm_elbow_pitch_motor">
       <hardwareInterface>EffortJointInterface</hardwareInterface>
       <mechanicalReduction>1</mechanicalReduction>
     </actuator>
  </transmission>

  <link name="r_arm_elbow_pitch_link">
    <collision>
      <origin xyz="0 0 0" rpy="0 0 0"/>
      <geometry>
          <mesh filename="package://erica_description/meshes/asm_don_big_arm_r-4.stl" scale="0.001 0.001 0.001"/>
        </geometry>
    </collision>

    <visual>
        <origin xyz="0 0 0" rpy="0 0 0"/>
        <geometry>
          <mesh filename="package://erica_description/meshes/asm_don_big_arm_r-4.stl" scale="0.001 0.001 0.001"/>
        </geometry>
        <material name="red"/>
    </visual>

    <inertial>
      <origin xyz="0 0 0" rpy="0 0 0"/>      
      <mass value="1"/>
      <inertia ixx="1.0" ixy="0.0" ixz="0.0" iyy="1.0" iyz="0.0" izz="1.0" />      
    </inertial>
  </link>

  <!-- right_arm_wrist_pitch -->

<joint name="r_arm_wrist_pitch" type="revolute">
    <parent link="r_arm_elbow_pitch_link"/>
    <child link="r_arm_wrist_pitch_link"/>
    <origin xyz="0 0 -0.2" rpy="0 0 0"/>
    <axis xyz="0 1 0"/>
    <limit velocity="6.5" effort="1000" lower="${-pi/2}" upper="${pi}" />
    <dynamics damping = "0.7"/>
  </joint>

  <transmission name="r_arm_wrist_pitch_tran">
     <type>transmission_interface/SimpleTransmission</type>
     <joint name="r_arm_wrist_pitch">
       <hardwareInterface>EffortJointInterface</hardwareInterface>
     </joint>
     <actuator name="r_arm_wrist_pitch_motor">
       <hardwareInterface>EffortJointInterface</hardwareInterface>
       <mechanicalReduction>1</mechanicalReduction>
     </actuator>
  </transmission>

  <link name="r_arm_wrist_pitch_link">
    <collision>
      <origin xyz="0 0 0" rpy="0 0 0"/>
      <geometry>
          <mesh filename="package://erica_description/meshes/asm_don_big_arm_r-5.stl" scale="0.001 0.001 0.001"/>
        </geometry>
    </collision>

    <visual>
        <origin xyz="0 0 0" rpy="0 0 0"/>
        <geometry>
          <mesh filename="package://erica_description/meshes/asm_don_big_arm_r-5.stl" scale="0.001 0.001 0.001"/>
        </geometry>
        <material name="red"/>
    </visual>

    <inertial>
      <origin xyz="0 0 0" rpy="0 0 0"/>      
      <mass value="1"/>
      <inertia ixx="1.0" ixy="0.0" ixz="0.0" iyy="1.0" iyz="0.0" izz="1.0" />      
    </inertial>
  </link>

<!-- right_arm_wrist_roll -->

<joint name="r_arm_wrist_roll" type="revolute">
    <parent link="r_arm_wrist_pitch_link"/>
    <child link="r_arm_wrist_roll_link"/>
    <origin xyz="0 0 0" rpy="0 0 0"/>
    <axis xyz="0 1 0"/>
    <limit velocity="6.5" effort="1000" lower="${-pi/2}" upper="${pi}" />
    <dynamics damping = "0.7"/>
  </joint>

  <transmission name="r_arm_wrist_roll_tran">
     <type>transmission_interface/SimpleTransmission</type>
     <joint name="r_arm_wrist_roll">
       <hardwareInterface>EffortJointInterface</hardwareInterface>
     </joint>
     <actuator name="r_arm_wrist_roll_motor">
       <hardwareInterface>EffortJointInterface</hardwareInterface>
       <mechanicalReduction>1</mechanicalReduction>
     </actuator>
  </transmission>

  <link name="r_arm_wrist_roll_link">
    <collision>
      <origin xyz="0 0 0" rpy="0 0 0"/>
      <geometry>
          <mesh filename="package://erica_description/meshes/asm_don_big_arm_r-6.stl" scale="0.001 0.001 0.001"/>
        </geometry>
    </collision>

    <visual>
        <origin xyz="0 0 0" rpy="0 0 0"/>
        <geometry>
          <mesh filename="package://erica_description/meshes/asm_don_big_arm_r-6.stl" scale="0.001 0.001 0.001"/>
        </geometry>
        <material name="red"/>
    </visual>

    <inertial>
      <origin xyz="0 0 0" rpy="0 0 0"/>      
      <mass value="1"/>
      <inertia ixx="1.0" ixy="0.0" ixz="0.0" iyy="1.0" iyz="0.0" izz="1.0" />      
    </inertial>
  </link>

</robot>



